<mujoco model="point_mass">
    <option timestep="0.01" />
    <option gravity="0 0 -9.81"/>
    <asset>
        <texture type="skybox" builtin="gradient" rgb1="0.3 0.5 0.7" rgb2="0 0 0" width="512" height="3072"/>
        <texture type="2d" name="groundplane" builtin="checker" mark="edge" rgb1="0.2 0.3 0.4" rgb2="0.1 0.2 0.3" markrgb="0.8 0.8 0.8" width="300" height="300"/>
        <material name="groundplane" texture="groundplane" texuniform="true" texrepeat="5 5" reflectance="0.2"/>
    </asset>
    <worldbody>
<!--        <geom size="20 20 .01" type="plane" material="grid"/>-->
        <body name="robot 1" pos="0 1 0" >
            <joint name="joint_x_robot1" type="slide" axis="1 0 0"/>  <!-- Translational joint along x-axis -->
            <joint name="joint_y_robot1" type="slide" axis="0 1 0"/>  <!-- Translational joint along y-axis -->
            <joint name="joint_z_robot1" type="slide" axis="0 0 1"/>  <!-- Translational joint along z-axis -->
            <geom type="sphere" size="0.1" mass="0.1" rgba="0.0 255.0 0.0 1.0"/> <!-- Visual representation -->
        </body>
        <body name="robot 2" pos="1 0 0" >
            <joint name="joint_x_robot2" type="slide" axis="1 0 0"/>  <!-- Translational joint along x-axis -->
            <joint name="joint_y_robot2" type="slide" axis="0 1 0"/>  <!-- Translational joint along y-axis -->
            <joint name="joint_z_robot2" type="slide" axis="0 0 1"/>  <!-- Translational joint along z-axis -->
            <geom type="sphere" size="0.1" mass="0.1" rgba="255.0 0.0 0.0 1.0"/> <!-- Visual representation -->
        </body>
        <light pos="0 0 1.5" dir="0 0 -1" directional="true"/>
        <geom name="floor" size="0 0 0.05" type="plane" material="groundplane"/>
    </worldbody>
    <actuator>
        <motor joint="joint_x_robot1" ctrlrange="-10 10" ctrllimited="true"/>
        <motor joint="joint_y_robot1" ctrlrange="-10 10" ctrllimited="true"/>
        <motor joint="joint_z_robot1" ctrlrange="-10 10" ctrllimited="true"/>
        <motor joint="joint_x_robot2" ctrlrange="-10 10" ctrllimited="true"/>
        <motor joint="joint_y_robot2" ctrlrange="-10 10" ctrllimited="true"/>
        <motor joint="joint_z_robot2" ctrlrange="-10 10" ctrllimited="true"/>
    </actuator>
</mujoco>
